size = 12 4 4
scale = 0.07
origin = -y
material lighting = smooth, roughness = 0.9, deform = 4
  colors = A:#5a3a24 B:#3f2819 C:#c9955e
voxels
------------ CABAAAABAAAC CAABAAAABAAC ------------
CAABAAAABAAC CAAABAAAABAC CAAAABAAAABC CBAAAABAAAAC
CAAAABAAAABC CBAAAABAAAAC CABAAAABAAAC CAABAAAABAAC
------------ CAABAAAABAAC CAAABAAAABAC ------------
